Workbook

Sheet Draft Board
A1: id | C1: name | D1: team | E1: position | F1: pick_number | G1: pick_player | H1: matches | I1: availability | J1: pts_avg_played | K1: pts_avg_all | L1: pts_std_played | M1: tier_position | N1: adp_position | O1: dvs_position_adj | P1: dvs_position | Q1: pts_z_played__vs_top_position | R1: pts_z_all__vs_top_position | S1: pts_avg_played__vs_top_position | T1: pts_avg_all__vs_top_position | U1: tier_general | V1: adp_general | W1: dvs_general_adj | X1: dvs_general | Y1: pts_z_played__vs_top_general | Z1: pts_z_all__vs_top_general | AA1: pts_avg_played__vs_top_general | AB1: pts_avg_all__vs_top_general
A2: 103445 | C2: Kaio Jorge | D2: CRU | E2: AT | F2: 1 | G2: =IFERROR(VLOOKUP(F2,Picks!$A$2:$B$231,2,0),"") -> Massa | H2: 33 | I2: 0.86842105 | J2: 9.46 | K2: 8.2152632 | L2: 2.1224552 | M2: S+ | N2: 1 | O2: 3.0287434 | P2: 3.1532123 | Q2: 2.9111844 | R2: 3.5162542 | S2: 3.7886667 | T2: 3.8563306 | U2: S+ | V2: 1 | W2: 4.0848217 | X2: 4.252691 | Y2: 4.1222086 | Z2: 4.4484147 | AA2: 4.55945 | AB2: 4.8135663
A3: 114802 | C3: Vitor Roque | D3: PAL | E3: AT | F3: 2 | G3: =IFERROR(VLOOKUP(F3,Picks!$A$2:$B$231,2,0),"") -> Vidal | H3: 31 | I3: 0.81578947 | J3: 8.31 | K3: 6.7792105 | L3: 1.9073868 | M3: S | N3: 2 | O3: 1.9832449 | P3: 2.0992564 | Q3: 2.0275326 | R3: 2.2068421 | S3: 2.6386667 | T3: 2.420278 | U3: S+ | V3: 3 | W3: 2.9268084 | X3: 3.0980144 | Y3: 3.0824911 | Z3: 3.1212993 | AA3: 3.40945 | AB3: 3.3775136
A4: 87863 | C4: Arrascaeta | D4: FLA | E4: MD | F4: 3 | G4: =IFERROR(VLOOKUP(F4,Picks!$A$2:$B$231,2,0),"") -> Fellipe | H4: 32 | I4: 0.84210526 | J4: 9.32 | K4: 7.8484211 | L4: 2.4696137 | M4: S+ | N4: 1 | O4: 3.449584 | P4: 3.6211103 | Q4: 3.5688174 | R4: 3.6995497 | S4: 4.4426667 | T4: 4.2508008 | U4: S+ | V4: 2 | W4: 3.8497184 | X4: 4.0411409 | Y4: 3.9956343 | Z4: 4.1094008 | AA4: 4.41945 | AB4: 4.4467241
A5: 94583 | C5: Pedro | D5: FLA | E5: AT | F5: 4 | G5: =IFERROR(VLOOKUP(F5,Picks!$A$2:$B$231,2,0),"") -> Carlos | H5: 21 | I5: 0.55263158 | J5: 7.74 | K5: 4.2773684 | L5: 2.9074624 | M5: S | N5: 5 | O5: 0.79997278 | P5: 0.92398072 | Q5: 1.5895487 | R5: -0.074371235 | S5: 2.0686667 | T5: -0.08156409 | U5: S | V5: 8 | W5: 1.6138224 | X5: 1.8639894 | Y5: 2.5671529 | Z5: 0.80924408 | AA5: 2.83945 | AB5: 0.87567151
A6: 96610 | C6: Matheus Pereira | D6: CRU | E6: MD | F6: 5 | G6: =IFERROR(VLOOKUP(F6,Picks!$A$2:$B$231,2,0),"") -> Fernando | H6: 34 | I6: 0.89473684 | J6: 7.03 | K6: 6.29 | L6: 1.8813904 | M6: S | N6: 2 | O6: 1.9124766 | P6: 1.97484 | Q6: 1.7292484 | R6: 2.3432274 | S6: 2.1526667 | T6: 2.6923798 | U6: S+ | V6: 4 | W6: 2.1526297 | X6: 2.2228241 | Y6: 1.9252404 | Z6: 2.6691997 | AA6: 2.12945 | AB6: 2.8883031
A7: 113103 | C7: Flaco López | D7: PAL | E7: AT | F7: 6 | G7: =IFERROR(VLOOKUP(F7,Picks!$A$2:$B$231,2,0),"") -> Rodolfo | H7: 30 | I7: 0.78947368 | J7: 6.8 | K7: 5.3684211 | L7: 1.267182 | M7: S | N7: 4 | O7: 0.83242331 | P7: 0.88854174 | Q7: 0.8672594 | R7: 0.92046524 | S7: 1.1286667 | T7: 1.0094885 | U7: S+ | V7: 6 | W7: 1.6463973 | X7: 1.7573904 | Y7: 1.7172969 | Z7: 1.8175307 | AA7: 1.89945 | AB7: 1.9667241
A8: 105563 | C8: Carlos Vinícius | D8: GRE | E8: AT | F8: 7 | G8: =IFERROR(VLOOKUP(F8,Picks!$A$2:$B$231,2,0),"") -> Petindá | H8: 13 | I8: 0.56521739 | J8: 7.97 | K8: 4.5047826 | L8: 3.0596222 | M8: S | N8: 3 | O8: 0.96779362 | P8: 1.1129627 | Q8: 1.766279 | R8: 0.13298808 | S8: 2.2986667 | T8: 0.1458501 | U8: S+ | V8: 5 | W8: 1.8024527 | X8: 2.0728206 | Y8: 2.7750964 | Z8: 1.0194069 | AA8: 3.06945 | AB8: 1.1030857
A9: 39148 | C9: Hulk | D9: CAM | E9: AT | F9: 8 | G9: =IFERROR(VLOOKUP(F9,Picks!$A$2:$B$231,2,0),"") -> Fochesato | H9: 27 | I9: 0.71052632 | J9: 6.19 | K9: 4.3981579 | L9: 1.1328216 | M9: A | N9: 10 | O9: 0.23142192 | P9: 0.25343035 | Q9: 0.39853976 | R9: 0.035766233 | S9: 0.51866667 | T9: 0.039225384 | U9: S- | V9: 14 | W9: 0.9750928 | X9: 1.067825 | Y9: 1.1657945 | Z9: 0.9208706 | AA9: 1.28945 | AB9: 0.99646099
A10: 83257 | C10: Gabriel | D10: SAN | E10: AT | F10: 9 | G10: =IFERROR(VLOOKUP(F10,Picks!$A$2:$B$231,2,0),"") -> Anuda | H10: 30 | I10: 0.78947368 | J10: 3.02 | K10: 2.3842105 | L10: 0.74620314 | M10: A- | N10: 20 | O10: -1.8199007 | P10: -1.9425906 | Q10: -2.0372656 | R10: -1.8005781 | S10: -2.6513333 | T10: -1.974722 | U10: A+ | V10: 63 | W10: -1.3080621 | X10: -1.396246 | Y10: -1.7002093 | Z10: -0.94030104 | AA10: -1.88055 | AB10: -1.0174864
A11: 100652 | C11: Yuri Alberto | D11: COR | E11: AT | F11: 10 | G11: =IFERROR(VLOOKUP(F11,Picks!$A$2:$B$231,2,0),"") -> Sousa | H11: 26 | I11: 0.68421053 | J11: 5.64 | K11: 3.8589474 | L11: 1.1321108 | M11: A+ | N11: 8 | O11: -0.17815856 | P11: -0.19680306 | Q11: -0.024076309 | R11: -0.45589318 | S11: -0.031333333 | T11: -0.49998514 | U11: A+ | V11: 23 | W11: 0.51613452 | X11: 0.5701486 | Y11: 0.66853835 | Z11: 0.42256397 | AA11: 0.73945 | AB11: 0.45725046
A12: 85048 | C12: Memphis Depay | D12: COR | E12: AT | F12: 11 | G12: =IFERROR(VLOOKUP(F12,Picks!$A$2:$B$231,2,0),"") -> Sousa | H12: 23 | I12: 0.60526316 | J12: 4.98 | K12: 3.0142105 | L12: 2.6377477 | M12: A- | N12: 19 | O12: -0.71335923 | P12: -0.8091836 | Q12: -0.53121559 | R12: -1.2261356 | S12: -0.69133333 | T12: -1.344722 | U12: B+ | V12: 62 | W12: -0.088279812 | X12: -0.10013829 | Y12: 0.071830917 | Z12: -0.35809211 | AA12: 0.07945 | AB12: -0.38748638
A13: 84735 | C13: Jorginho | D13: FLA | E13: MD | F13: 12 | G13: =IFERROR(VLOOKUP(F13,Picks!$A$2:$B$231,2,0),"") -> Anuda | H13: 17 | I13: 0.62962963 | J13: 3.61 | K13: 2.272963 | L13: 0.86994318 | M13: B | N13: 30 | O13: -0.95287348 | P13: -1.0719827 | Q13: -1.0180555 | R13: -1.1528734 | S13: -1.2673333 | T13: -1.3246572 | U13: C+ | V13: 136 | W13: -0.99317087 | X13: -1.1173172 | Y13: -1.1667891 | Z13: -1.0431095 | AA13: -1.29055 | AB13: -1.1287339
... A24: 142890 | C24: Montoro | D24: BOT | E24: MD | F24: 23 | G24: =IFERROR(VLOOKUP(F24,Picks!$A$2:$B$231,2,0),"") -> Fellipe | H24: 14 | I24: 0.51851852 | J24: 4.9 | K24: 2.5407407 | L24: 1.0598053 | M24: A+ | N24: 8 | O24: -0.30543646 | P24: -0.35700366 | Q24: 0.018208252 | R24: -0.91982153 | S24: 0.022666667 | T24: -1.0568795 | U24: B+ | V24: 64 | W24: -0.27254267 | X24: -0.31855636 | Y24: -0.00049725619 | Z24: -0.79564502 | AA24: -0.00055 | AB24: -0.86095617
A25: 112709 | C25: Kaiki Bruno | D25: CRU | E25: FB | F25: 24 | G25: =IFERROR(VLOOKUP(F25,Picks!$A$2:$B$231,2,0),"") -> Carlos | H25: 34 | I25: 0.89473684 | J25: 7.34 | K25: 6.5673684 | L25: 1.3489804 | O25: 1.4380753 | P25: 1.484969 | Q25: 1.1270009 | R25: 2.0219212 | S25: 1.0025 | T25: 1.8417753 | W25: 2.4147755 | X25: 2.4935181 | Y25: 2.205512 | Z25: 2.9255273 | AA25: 2.43945 | AB25: 3.1656715
A26: 89275 | C26: William | D26: CRU | E26: FB | F26: 25 | G26: =IFERROR(VLOOKUP(F26,Picks!$A$2:$B$231,2,0),"") -> Fernando | H26: 30 | I26: 0.78947368 | J26: 7.39 | K26: 5.8342105 | L26: 2.3231651 | M26: S | N26: 3 | O26: 1.1211632 | P26: 1.1967472 | Q26: 1.1832104 | R26: 1.2170524 | S26: 1.0525 | T26: 1.1086174 | U26: S | V26: 13 | W26: 2.1075431 | X26: 2.2496247 | Y26: 2.2507171 | Z26: 2.2479859 | AA26: 2.48945 | AB26: 2.4325136
A27: 72493 | C27: Alex Telles | D27: BOT | E27: FB | F27: 26 | G27: =IFERROR(VLOOKUP(F27,Picks!$A$2:$B$231,2,0),"") -> Rodolfo | H27: 23 | I27: 0.60526316 | J27: 5.71 | K27: 3.4560526 | L27: 1.0131157 | M27: B+ | N27: 13 | O27: -0.86460319 | P27: -0.98074392 | Q27: -0.7054295 | R27: -1.3937155 | S27: -0.6275 | T27: -1.2695405 | U27: A | V27: 36 | W27: 0.40481069 | X27: 0.45918824 | Y27: 0.7318255 | Z27: 0.050232361 | AA27: 0.80945 | AB27: 0.054355724
A28: 89256 | C28: Gerson | D28: CRU | E28: MD | F28: 27 | G28: =IFERROR(VLOOKUP(F28,Picks!$A$2:$B$231,2,0),"") -> Petindá | M28: B | N28: 36 | U28: B- | V28: 105
A29: 105436 | C29: Carrascal | D29: FLA | E29: MD | F29: 28 | G29: =IFERROR(VLOOKUP(F29,Picks!$A$2:$B$231,2,0),"") -> Fochesato | H29: 15 | I29: 0.71428571 | J29: 5.33 | K29: 3.8071429 | L29: 2.1900874 | M29: A+ | N29: 7 | O29: 0.26616527 | P29: 0.29111826 | Q29: 0.3636295 | R29: 0.1823514 | S29: 0.45266667 | T29: 0.20952265 | U29: A | V29: 35 | W29: 0.35002123 | X29: 0.38283572 | Y29: 0.38826668 | Z29: 0.37468929 | AA29: 0.42945 | AB29: 0.40544595
A30: 86757 | C30: Everton | D30: FLA | E30: AT | F30: 29 | G30: =IFERROR(VLOOKUP(F30,Picks!$A$2:$B$231,2,0),"") -> Anuda | H30: 21 | I30: 0.55263158 | J30: 2.27 | K30: 1.2544737 | L30: 0.81094789 | M30: D | N30: 62 | O30: -2.3379875 | P30: -2.7004111 | Q30: -2.6135602 | R30: -2.8306874 | S30: -3.4013333 | T30: -3.1044588 | U30: D+ | V30: 242 | W30: -1.9226643 | X30: -2.2207065 | Y30: -2.378286 | Z30: -1.9843373 | AA30: -2.63055 | AB30: -2.1472232
A31: 83528 | C31: Léo Pereira | D31: FLA | E31: CB | F31: 30 | G31: =IFERROR(VLOOKUP(F31,Picks!$A$2:$B$231,2,0),"") -> Sousa | H31: 32 | I31: 0.84210526 | J31: 4.84 | K31: 4.0757895 | L31: 0.86887122 | M31: S | N31: 1 | O31: 0.49900605 | P31: 0.5238185 | Q31: -0.042840841 | R31: 1.3738075 | S31: -0.017 | T31: 0.76218431 | U31: A | V31: 38 | W31: 0.20608912 | X31: 0.21633664 | Y31: -0.054743386 | Z31: 0.62295668 | AA31: -0.06055 | AB31: 0.67409257
A32: 61987 | C32: Alex Sandro | D32: FLA | E32: FB | F32: 31 | G32: =IFERROR(VLOOKUP(F32,Picks!$A$2:$B$231,2,0),"") -> Sousa | H32: 20 | I32: 0.52631579 | J32: 3.99 | K32: 2.1 | L32: 0.85487374 | M32: C | N32: 34 | O32: -2.3475297 | P32: -2.7363843 | Q32: -2.6390371 | R32: -2.8824051 | S32: -2.3475 | T32: -2.6255931 | U32: C | V32: 160 | W32: -0.83654929 | X32: -0.97511881 | Y32: -0.82323023 | Z32: -1.2029517 | AA32: -0.91055 | AB32: -1.3016969
A33: 97867 | C33: Léo Ortiz | D33: FLA | E33: CB | F33: 32 | G33: =IFERROR(VLOOKUP(F33,Picks!$A$2:$B$231,2,0),"") -> Anuda | H33: 26 | I33: 0.68421053 | J33: 4.77 | K33: 3.2636842 | L33: 1.4357056 | M33: A | N33: 10 | O33: -0.15166672 | P33: -0.16753881 | Q33: -0.21924431 | R33: -0.089980574 | S33: -0.087 | T33: -0.049920954 | U33: B- | V33: 112 | W33: -0.11029329 | X33: -0.12183561 | Y33: -0.11803054 | Z33: -0.12754321 | AA33: -0.13055 | AB33: -0.1380127
A34: 92854 | C34: Borré | D34: INT | E34: AT | F34: 33 | G34: =IFERROR(VLOOKUP(F34,Picks!$A$2:$B$231,2,0),"") -> Fochesato | H34: 29 | I34: 0.76315789 | J34: 3.98 | K34: 3.0373684 | L34: 0.74314358 | M34: C+ | N34: 43 | O34: -1.1721207 | P34: -1.261773 | Q34: -1.2996085 | R34: -1.2050199 | S34: -1.6913333 | T34: -1.3215641 | U34: C+ | V34: 126 | W34: -0.58898898 | X34: -0.63403913 | Y34: -0.83227125 | Z34: -0.33669095 | AA34: -0.92055 | AB34: -0.36432849
A35: 109573 | C35: Martinelli | D35: FLU | E35: MD | F35: 34 | G35: =IFERROR(VLOOKUP(F35,Picks!$A$2:$B$231,2,0),"") -> Petindá | H35: 31 | I35: 0.81578947 | J35: 2.7 | K35: 2.2026316 | L35: 1.1331532 | M35: C | N35: 58 | O35: -1.4502387 | P35: -1.5350716 | Q35: -1.7490633 | R35: -1.2140841 | S35: -2.1773333 | T35: -1.3949886 | U35: C- | V35: 212 | W35: -1.5464921 | X35: -1.6369555 | Y35: -1.989522 | Z35: -1.1081056 | AA35: -2.20055 | AB35: -1.1990653
A36: 109401 | C36: Erick Pulga | D36: BAH | E36: AT | F36: 35 | G36: =IFERROR(VLOOKUP(F36,Picks!$A$2:$B$231,2,0),"") -> Rodolfo | H36: 24 | I36: 0.63157895 | J36: 5.64 | K36: 3.5621053 | L36: 1.2099467 | M36: A+ | N36: 9 | O36: -0.27135077 | P36: -0.30506891 | Q36: -0.024076309 | R36: -0.72655781 | S36: -0.031333333 | T36: -0.79682725 | U36: A+ | V36: 24 | W36: 0.40953058 | X36: 0.46041899 | Y36: 0.66853835 | Z36: 0.14823996 | AA36: 0.73945 | AB36: 0.16040836
A37: 132553 | C37: Jemmes | D37: FLU | E37: CB | F37: 36 | G37: =IFERROR(VLOOKUP(F37,Picks!$A$2:$B$231,2,0),"") -> Fernando | H37: 34 | I37: 0.91891892 | J37: 4.53 | K37: 4.1627027 | L37: 1.030088 | M37: A | N37: 8 | O37: 0.11488813 | P37: 0.11775238 | Q37: -0.82405618 | R37: 1.5304652 | S37: -0.327 | T37: 0.84909754 | U37: A- | V37: 58 | W37: 0.07834839 | X37: 0.080301674 | Y37: -0.33501506 | Z37: 0.70327677 | AA37: -0.37055 | AB37: 0.7610058
A38: 99552 | C38: Rossi | D38: FLA | E38: GK | F38: 37 | G38: =IFERROR(VLOOKUP(F38,Picks!$A$2:$B$231,2,0),"") -> Carlos | H38: 35 | I38: 0.92105263 | J38: 5.61 | K38: 5.1671053 | L38: 1.6156505 | M38: S+ | N38: 1 | O38: 0.58265806 | P38: 0.59679263 | Q38: 0.054826233 | R38: 1.4097422 | S38: 0.069 | T38: 1.0054651 | U38: S- | V38: 15 | W38: 1.0128727 | X38: 1.0374438 | Y38: 0.64141528 | Z38: 1.6314865 | AA38: 0.70945 | AB38: 1.7654084
A39: 109096 | C39: Plata | D39: FLA | E39: AT | F39: 38 | G39: =IFERROR(VLOOKUP(F39,Picks!$A$2:$B$231,2,0),"") -> Fellipe | H39: 27 | I39: 0.71052632 | J39: 3.25 | K39: 2.3092105 | L39: 0.94779117 | M39: D+ | N39: 59 | O39: -1.7020412 | P39: -1.8639068 | Q39: -1.8605352 | R39: -1.8689641 | S39: -2.4213333 | T39: -2.049722 | U39: D+ | V39: 231 | W39: -1.1863785 | X39: -1.2992041 | Y39: -1.4922658 | Z39: -1.0096116 | AA39: -1.65055 | AB39: -1.0924864
A40: 143193 | C40: Viveros | D40: CAP | E40: AT | F40: 39 | G40: =IFERROR(VLOOKUP(F40,Picks!$A$2:$B$231,2,0),"") -> Vidal | M40: B+ | N40: 26 | U40: A- | V40: 57
A41: 107093 | C41: Luciano Juba | D41: BAH | E41: FB | F41: 40 | G41: =IFERROR(VLOOKUP(F41,Picks!$A$2:$B$231,2,0),"") -> Massa | H41: 33 | I41: 0.86842105 | J41: 5.53 | K41: 4.8023684 | L41: 1.4546786 | M41: A | N41: 7 | O41: -0.49078703 | P41: -0.51095636 | Q41: -0.90778378 | R41: 0.084284775 | S41: -0.8075 | T41: 0.076775304 | U41: S- | V41: 17 | W41: 0.82530298 | X41: 0.85921954 | Y41: 0.56908711 | Z41: 1.2944182 | AA41: 0.62945 | AB41: 1.4006715
A42: 104084 | C42: Carlos Miguel | D42: PAL | E42: GK | F42: 41 | G42: =IFERROR(VLOOKUP(F42,Picks!$A$2:$B$231,2,0),"") -> Massa | H42: 6 | I42: 0.31578947 | J42: 8.52 | K42: 2.6905263 | L42: 4.3045122 | M42: S | N42: 3 | O42: 0.47301969 | P42: 0.59519034 | Q42: 2.367063 | R42: -2.0626187 | S42: 2.979 | T42: -1.4711138 | U42: S- | V42: 19 | W42: 1.3514681 | X42: 1.7005228 | Y42: 3.2723526 | Z42: -0.65722201 | AA42: 3.61945 | AB42: -0.71117059
A43: 70360 | C43: Eduardo Sasha | D43: RBB | E43: AT | F43: 42 | G43: =IFERROR(VLOOKUP(F43,Picks!$A$2:$B$231,2,0),"") -> Vidal | H43: 30 | I43: 0.78947368 | J43: 3.95 | K43: 3.1184211 | L43: 1.1402664 | M43: B- | N43: 38 | O43: -1.1673448 | P43: -1.2460422 | Q43: -1.3226602 | R43: -1.131115 | S43: -1.7213333 | T43: -1.2405115 | U43: B | V43: 93 | W43: -0.58117125 | X43: -0.62035134 | Y43: -0.85939432 | Z43: -0.26178687 | AA43: -0.95055 | AB43: -0.28327585
A44: 132071 | C44: Serna | D44: FLU | E44: AT | F44: 43 | G44: =IFERROR(VLOOKUP(F44,Picks!$A$2:$B$231,2,0),"") -> Fellipe | H44: 32 | I44: 0.84210526 | J44: 5.21 | K44: 4.3873684 | L44: 1.4420347 | M44: A | N44: 11 | O44: -0.19273627 | P44: -0.20231984 | Q44: -0.35448524 | R44: 0.025928246 | S44: -0.46133333 | T44: 0.02843591 | U44: A+ | V44: 28 | W44: 0.50701386 | X44: 0.53222449 | Y44: 0.27977442 | Z44: 0.91089961 | AA44: 0.30945 | AB44: 0.98567151
A45: 73384 | C45: Samuel Xavier | D45: FLU | E45: FB | F45: 44 | G45: =IFERROR(VLOOKUP(F45,Picks!$A$2:$B$231,2,0),"") -> Carlos | H45: 27 | I45: 0.71052632 | J45: 5.61 | K45: 3.9860526 | L45: 1.4276222 | M45: B | N45: 15 | O45: -0.7446432 | P45: -0.81545941 | Q45: -0.81784855 | R45: -0.8118757 | S45: -0.7275 | T45: -0.73954049 | U45: A | V45: 41 | W45: 0.54868009 | X45: 0.60086004 | Y45: 0.64141528 | Z45: 0.54002717 | AA45: 0.70945 | AB45: 0.58435572
A46: 42234 | C46: Cássio | D46: CRU | E46: GK | F46: 45 | G46: =IFERROR(VLOOKUP(F46,Picks!$A$2:$B$231,2,0),"") -> Fernando | H46: 35 | I46: 0.92105263 | J46: 5.52 | K46: 5.0842105 | L46: 1.0843089 | M46: S+ | N46: 2 | O46: 0.49537788 | P46: 0.50739513 | Q46: -0.016686245 | R46: 1.2935172 | S46: -0.021 | T46: 0.92257041 | U46: S- | V46: 18 | W46: 0.93529069 | X46: 0.95797968 | Y46: 0.56004609 | Z46: 1.5548801 | AA46: 0.61945 | AB46: 1.6825136
A47: 102928 | C47: Canobbio | D47: FLU | E47: AT | F47: 46 | G47: =IFERROR(VLOOKUP(F47,Picks!$A$2:$B$231,2,0),"") -> Rodolfo | H47: 28 | I47: 0.73684211 | J47: 5.28 | K47: 3.8905263 | L47: 1.0490683 | M47: A | N47: 12 | O47: -0.32352736 | P47: -0.35125827 | Q47: -0.30069774 | R47: -0.42709908 | S47: -0.39133333 | T47: -0.46840619 | U47: A | V47: 29 | W47: 0.3560199 | X47: 0.38653589 | Y47: 0.34306157 | Z47: 0.45174737 | AA47: 0.37945 | AB47: 0.48882941
A48: 99274 | C48: Alexander Barboza | D48: BOT | E48: CB | F48: 47 | G48: =IFERROR(VLOOKUP(F48,Picks!$A$2:$B$231,2,0),"") -> Petindá | H48: 21 | I48: 0.55263158 | J48: 5.05 | K48: 2.7907895 | L48: 1.155379 | M48: A+ | N48: 7 | O48: -0.073696202 | P48: -0.085120234 | Q48: 0.48636955 | R48: -0.94235491 | S48: 0.193 | T48: -0.52281569 | U48: B+ | V48: 66 | W48: -0.12532739 | X48: -0.14475504 | Y48: 0.13511807 | Z48: -0.5645647 | AA48: 0.14945 | AB48: -0.61090743
A49: 96591 | C49: Renan Lodi | D49: CAM | E49: FB | F49: 48 | G49: =IFERROR(VLOOKUP(F49,Picks!$A$2:$B$231,2,0),"") -> Fochesato | M49: A | N49: 9 | U49: A+ | V49: 27
A50: 101314 | C50: Ademir | D50: BAH | E50: AT | F50: 49 | G50: =IFERROR(VLOOKUP(F50,Picks!$A$2:$B$231,2,0),"") -> Anuda | H50: 29 | I50: 0.76315789 | J50: 4.65 | K50: 3.5486842 | L50: 0.98392138 | M50: B+ | N50: 22 | O50: -0.71193529 | P50: -0.76638927 | Q50: -0.78478524 | R50: -0.73879531 | S50: -1.0213333 | T50: -0.8102483 | U50: A- | V50: 61 | W50: -0.075782479 | X50: -0.081578873 | Y50: -0.2265228 | Z50: 0.13583702 | AA50: -0.25055 | AB50: 0.1469873
...

Sheet My Picks
A1: Round | B1: Pick | C1: Player | E1: Squad
A2: 1 | B2: 1 | C2: =IFERROR(INDEX('Draft Board'!$A$1:$Z$622,MATCH(B2,'Draft Board'!$F$1:$F$622,0),3),"") -> Kaio Jorge | E2: GK | F2: Carlos Miguel
A3: 2 | B3: 20 | C3: =IFERROR(INDEX('Draft Board'!$A$1:$Z$622,MATCH(B3,'Draft Board'!$F$1:$F$622,0),3),"") -> Samuel Lino | F3: Rafael
A4: 3 | B4: 21 | C4: =IFERROR(INDEX('Draft Board'!$A$1:$Z$622,MATCH(B4,'Draft Board'!$F$1:$F$622,0),3),"") -> Paulo Henrique | E4: CB | F4: Fabrício Bruno | G4: Vitor Hugo
A5: 4 | B5: 40 | C5: =IFERROR(INDEX('Draft Board'!$A$1:$Z$622,MATCH(B5,'Draft Board'!$F$1:$F$622,0),3),"") -> Luciano Juba | F5: Terán | G5: Adonis Frías
A6: 5 | B6: 41 | C6: =IFERROR(INDEX('Draft Board'!$A$1:$Z$622,MATCH(B6,'Draft Board'!$F$1:$F$622,0),3),"") -> Carlos Miguel | E6: FB | F6: Paulo Henrique | G6: Luciano Juba
A7: 6 | B7: 60 | C7: =IFERROR(INDEX('Draft Board'!$A$1:$Z$622,MATCH(B7,'Draft Board'!$F$1:$F$622,0),3),"") -> Fabrício Bruno | F7: Vitinho | G7: Maik | H7: Walter Clar
A8: 7 | B8: 61 | C8: =IFERROR(INDEX('Draft Board'!$A$1:$Z$622,MATCH(B8,'Draft Board'!$F$1:$F$622,0),3),"") -> Erick | E8: MD | F8: Lucas Romero | G8: Jean Lucas | H8: Raniele
A9: 8 | B9: 80 | C9: =IFERROR(INDEX('Draft Board'!$A$1:$Z$622,MATCH(B9,'Draft Board'!$F$1:$F$622,0),3),"") -> Lucas Romero | F9: Josué | G9: Felipinho | H9: Zé Rafael
A10: 9 | B10: 81 | C10: =IFERROR(INDEX('Draft Board'!$A$1:$Z$622,MATCH(B10,'Draft Board'!$F$1:$F$622,0),3),"") -> Jean Lucas | E10: AT | F10: Kaio Jorge | G10: Samuel Lino | H10: Erick
A11: 10 | B11: 100 | C11: =IFERROR(INDEX('Draft Board'!$A$1:$Z$622,MATCH(B11,'Draft Board'!$F$1:$F$622,0),3),"") -> Vitinho | F11: Lucas Barbosa | G11: Galeano | H11: Pedro Rocha
A12: 11 | B12: 101 | C12: =IFERROR(INDEX('Draft Board'!$A$1:$Z$622,MATCH(B12,'Draft Board'!$F$1:$F$622,0),3),"") -> Lucas Barbosa
A13: 12 | B13: 120 | C13: =IFERROR(INDEX('Draft Board'!$A$1:$Z$622,MATCH(B13,'Draft Board'!$F$1:$F$622,0),3),"") -> Raniele
A14: 13 | B14: 121 | C14: =IFERROR(INDEX('Draft Board'!$A$1:$Z$622,MATCH(B14,'Draft Board'!$F$1:$F$622,0),3),"") -> Vitor Hugo
A15: 14 | B15: 140 | C15: =IFERROR(INDEX('Draft Board'!$A$1:$Z$622,MATCH(B15,'Draft Board'!$F$1:$F$622,0),3),"") -> Rafael
A16: 15 | B16: 141 | C16: =IFERROR(INDEX('Draft Board'!$A$1:$Z$622,MATCH(B16,'Draft Board'!$F$1:$F$622,0),3),"") -> Josué
A17: 16 | B17: 160 | C17: =IFERROR(INDEX('Draft Board'!$A$1:$Z$622,MATCH(B17,'Draft Board'!$F$1:$F$622,0),3),"") -> Galeano
A18: 17 | B18: 161 | C18: =IFERROR(INDEX('Draft Board'!$A$1:$Z$622,MATCH(B18,'Draft Board'!$F$1:$F$622,0),3),"") -> Maik
A19: 18 | B19: 180 | C19: Pedro Rocha
A20: 19 | B20: 181 | C20: Felipinho
A21: 20 | B21: 200 | C21: Terán
A22: 21 | B22: 201 | C22: Adonis Frías
A23: 22 | B23: 220 | C23: Zé Rafael
A24: 23 | B24: 221 | C24: Walter Clar

Sheet Picks
A1: Number | B1: GM
A2: 1 | B2: Massa
A3: 2 | B3: Vidal
A4: 3 | B4: Fellipe
A5: 4 | B5: Carlos
A6: 5 | B6: Fernando
A7: 6 | B7: Rodolfo
A8: 7 | B8: Petindá
A9: 8 | B9: Fochesato
A10: 9 | B10: Anuda
A11: 10 | B11: Sousa
A12: 11 | B12: Sousa
A13: 12 | B13: Anuda
... A231: 230 | B231: Sousa

Sheet Post-Mortem
B1: Pick Number | L1: Pick Player | V1: Tier General | AF1: Average Draft Position | AP1: Pick Number - ADP
A2: Round | B2: Massa | C2: Vidal | D2: Fellipe | E2: Carlos | F2: Fernando | G2: Rodolfo | H2: Petindá | I2: Fochesato | J2: Anuda | K2: Sousa | L2: Massa | M2: Vidal | N2: Fellipe | O2: Carlos | P2: Fernando | Q2: Rodolfo | R2: Petindá | S2: Fochesato | T2: Anuda | U2: Sousa | V2: Massa | W2: Vidal | X2: Fellipe | Y2: Carlos | Z2: Fernando | AA2: Rodolfo | AB2: Petindá | AC2: Fochesato | AD2: Anuda | AE2: Sousa | AF2: Massa | AG2: Vidal | AH2: Fellipe | AI2: Carlos | AJ2: Fernando | AK2: Rodolfo | AL2: Petindá | AM2: Fochesato | AN2: Anuda | AO2: Sousa | AP2: Massa | AQ2: Vidal | AR2: Fellipe | AS2: Carlos | AT2: Fernando | AU2: Rodolfo | AV2: Petindá | AW2: Fochesato | AX2: Anuda | AY2: Sousa
A3: 1 | B3: 1 | C3: 2 | D3: 3 | E3: 4 | F3: 5 | G3: 6 | H3: 7 | I3: 8 | J3: 9 | K3: 10 | L3: =INDEX('Draft Board'!$A$2:$AB$622,MATCH('Post-Mortem'!B3,'Draft Board'!$F$2:$F$622,0),3) -> Kaio Jorge | M3: =INDEX('Draft Board'!$A$2:$AB$622,MATCH('Post-Mortem'!C3,'Draft Board'!$F$2:$F$622,0),3) -> Vitor Roque | N3: =INDEX('Draft Board'!$A$2:$AB$622,MATCH('Post-Mortem'!D3,'Draft Board'!$F$2:$F$622,0),3) -> Arrascaeta | O3: =INDEX('Draft Board'!$A$2:$AB$622,MATCH('Post-Mortem'!E3,'Draft Board'!$F$2:$F$622,0),3) -> Pedro | P3: =INDEX('Draft Board'!$A$2:$AB$622,MATCH('Post-Mortem'!F3,'Draft Board'!$F$2:$F$622,0),3) -> Matheus Pereira | Q3: =INDEX('Draft Board'!$A$2:$AB$622,MATCH('Post-Mortem'!G3,'Draft Board'!$F$2:$F$622,0),3) -> Flaco López | R3: =INDEX('Draft Board'!$A$2:$AB$622,MATCH('Post-Mortem'!H3,'Draft Board'!$F$2:$F$622,0),3) -> Carlos Vinícius | S3: =INDEX('Draft Board'!$A$2:$AB$622,MATCH('Post-Mortem'!I3,'Draft Board'!$F$2:$F$622,0),3) -> Hulk | ... U3: =INDEX('Draft Board'!$A$2:$AB$622,MATCH('Post-Mortem'!K3,'Draft Board'!$F$2:$F$622,0),3) -> Yuri Alberto | V3: =INDEX('Draft Board'!$A$2:$AB$622,MATCH('Post-Mortem'!B3,'Draft Board'!$F$2:$F$622,0),21) -> S+ | W3: =INDEX('Draft Board'!$A$2:$AB$622,MATCH('Post-Mortem'!C3,'Draft Board'!$F$2:$F$622,0),21) -> S+ | X3: =INDEX('Draft Board'!$A$2:$AB$622,MATCH('Post-Mortem'!D3,'Draft Board'!$F$2:$F$622,0),21) -> S+ | Y3: =INDEX('Draft Board'!$A$2:$AB$622,MATCH('Post-Mortem'!E3,'Draft Board'!$F$2:$F$622,0),21) -> S | Z3: =INDEX('Draft Board'!$A$2:$AB$622,MATCH('Post-Mortem'!F3,'Draft Board'!$F$2:$F$622,0),21) -> S+ | AA3: =INDEX('Draft Board'!$A$2:$AB$622,MATCH('Post-Mortem'!G3,'Draft Board'!$F$2:$F$622,0),21) -> S+ | AB3: =INDEX('Draft Board'!$A$2:$AB$622,MATCH('Post-Mortem'!H3,'Draft Board'!$F$2:$F$622,0),21) -> S+ | AC3: =INDEX('Draft Board'!$A$2:$AB$622,MATCH('Post-Mortem'!I3,'Draft Board'!$F$2:$F$622,0),21) -> S- | ... AE3: =INDEX('Draft Board'!$A$2:$AB$622,MATCH('Post-Mortem'!K3,'Draft Board'!$F$2:$F$622,0),21) -> A+ | AF3: =INDEX('Draft Board'!$A$2:$AB$622,MATCH('Post-Mortem'!B3,'Draft Board'!$F$2:$F$622,0),22) -> 1 | AG3: =INDEX('Draft Board'!$A$2:$AB$622,MATCH('Post-Mortem'!C3,'Draft Board'!$F$2:$F$622,0),22) -> 3 | AH3: =INDEX('Draft Board'!$A$2:$AB$622,MATCH('Post-Mortem'!D3,'Draft Board'!$F$2:$F$622,0),22) -> 2 | AI3: =INDEX('Draft Board'!$A$2:$AB$622,MATCH('Post-Mortem'!E3,'Draft Board'!$F$2:$F$622,0),22) -> 8 | AJ3: =INDEX('Draft Board'!$A$2:$AB$622,MATCH('Post-Mortem'!F3,'Draft Board'!$F$2:$F$622,0),22) -> 4 | AK3: =INDEX('Draft Board'!$A$2:$AB$622,MATCH('Post-Mortem'!G3,'Draft Board'!$F$2:$F$622,0),22) -> 6 | AL3: =INDEX('Draft Board'!$A$2:$AB$622,MATCH('Post-Mortem'!H3,'Draft Board'!$F$2:$F$622,0),22) -> 5 | AM3: =INDEX('Draft Board'!$A$2:$AB$622,MATCH('Post-Mortem'!I3,'Draft Board'!$F$2:$F$622,0),22) -> 14 | ... AO3: =INDEX('Draft Board'!$A$2:$AB$622,MATCH('Post-Mortem'!K3,'Draft Board'!$F$2:$F$622,0),22) -> 23 | AP3: =B3-AF3 -> 0 | AQ3: =C3-AG3 -> -1 | AR3: =D3-AH3 -> 1 | AS3: =E3-AI3 -> -4 | AT3: =F3-AJ3 -> 1 | AU3: =G3-AK3 -> 0 | AV3: =H3-AL3 -> 2 | AW3: =I3-AM3 -> -6 | ... AY3: =K3-AO3 -> -13
A4: =A3+1 -> 2 | B4: =B3+20-B3 -> 20 | C4: 19 | D4: 18 | E4: 17 | F4: 16 | G4: 15 | H4: 14 | I4: 13 | J4: 12 | K4: 11 | L4: =INDEX('Draft Board'!$A$2:$AB$622,MATCH('Post-Mortem'!B4,'Draft Board'!$F$2:$F$622,0),3) -> Samuel Lino | M4: =INDEX('Draft Board'!$A$2:$AB$622,MATCH('Post-Mortem'!C4,'Draft Board'!$F$2:$F$622,0),3) -> Barreal | N4: =INDEX('Draft Board'!$A$2:$AB$622,MATCH('Post-Mortem'!D4,'Draft Board'!$F$2:$F$622,0),3) -> Danilo | O4: =INDEX('Draft Board'!$A$2:$AB$622,MATCH('Post-Mortem'!E4,'Draft Board'!$F$2:$F$622,0),3) -> Luciano | P4: =INDEX('Draft Board'!$A$2:$AB$622,MATCH('Post-Mortem'!F4,'Draft Board'!$F$2:$F$622,0),3) -> Willian José | Q4: =INDEX('Draft Board'!$A$2:$AB$622,MATCH('Post-Mortem'!G4,'Draft Board'!$F$2:$F$622,0),3) -> Alan Patrick | R4: =INDEX('Draft Board'!$A$2:$AB$622,MATCH('Post-Mortem'!H4,'Draft Board'!$F$2:$F$622,0),3) -> Reinaldo | S4: =INDEX('Draft Board'!$A$2:$AB$622,MATCH('Post-Mortem'!I4,'Draft Board'!$F$2:$F$622,0),3) -> Neymar | ... U4: =INDEX('Draft Board'!$A$2:$AB$622,MATCH('Post-Mortem'!K4,'Draft Board'!$F$2:$F$622,0),3) -> Memphis Depay | V4: =INDEX('Draft Board'!$A$2:$AB$622,MATCH('Post-Mortem'!B4,'Draft Board'!$F$2:$F$622,0),21) -> S | W4: =INDEX('Draft Board'!$A$2:$AB$622,MATCH('Post-Mortem'!C4,'Draft Board'!$F$2:$F$622,0),21) -> A | X4: =INDEX('Draft Board'!$A$2:$AB$622,MATCH('Post-Mortem'!D4,'Draft Board'!$F$2:$F$622,0),21) -> C | Y4: =INDEX('Draft Board'!$A$2:$AB$622,MATCH('Post-Mortem'!E4,'Draft Board'!$F$2:$F$622,0),21) -> A+ | Z4: =INDEX('Draft Board'!$A$2:$AB$622,MATCH('Post-Mortem'!F4,'Draft Board'!$F$2:$F$622,0),21) -> A | AA4: =INDEX('Draft Board'!$A$2:$AB$622,MATCH('Post-Mortem'!G4,'Draft Board'!$F$2:$F$622,0),21) -> S | AB4: =INDEX('Draft Board'!$A$2:$AB$622,MATCH('Post-Mortem'!H4,'Draft Board'!$F$2:$F$622,0),21) -> S+ | AC4: =INDEX('Draft Board'!$A$2:$AB$622,MATCH('Post-Mortem'!I4,'Draft Board'!$F$2:$F$622,0),21) -> S | ... AE4: =INDEX('Draft Board'!$A$2:$AB$622,MATCH('Post-Mortem'!K4,'Draft Board'!$F$2:$F$622,0),21) -> B+ | AF4: =INDEX('Draft Board'!$A$2:$AB$622,MATCH('Post-Mortem'!B4,'Draft Board'!$F$2:$F$622,0),22) -> 11 | AG4: =INDEX('Draft Board'!$A$2:$AB$622,MATCH('Post-Mortem'!C4,'Draft Board'!$F$2:$F$622,0),22) -> 33 | AH4: =INDEX('Draft Board'!$A$2:$AB$622,MATCH('Post-Mortem'!D4,'Draft Board'!$F$2:$F$622,0),22) -> 182 | AI4: =INDEX('Draft Board'!$A$2:$AB$622,MATCH('Post-Mortem'!E4,'Draft Board'!$F$2:$F$622,0),22) -> 22 | AJ4: =INDEX('Draft Board'!$A$2:$AB$622,MATCH('Post-Mortem'!F4,'Draft Board'!$F$2:$F$622,0),22) -> 43 | AK4: =INDEX('Draft Board'!$A$2:$AB$622,MATCH('Post-Mortem'!G4,'Draft Board'!$F$2:$F$622,0),22) -> 10 | AL4: =INDEX('Draft Board'!$A$2:$AB$622,MATCH('Post-Mortem'!H4,'Draft Board'!$F$2:$F$622,0),22) -> 7 | AM4: =INDEX('Draft Board'!$A$2:$AB$622,MATCH('Post-Mortem'!I4,'Draft Board'!$F$2:$F$622,0),22) -> 9 | ... AO4: =INDEX('Draft Board'!$A$2:$AB$622,MATCH('Post-Mortem'!K4,'Draft Board'!$F$2:$F$622,0),22) -> 62 | AP4: =B4-AF4 -> 9 | AQ4: =C4-AG4 -> -14 | AR4: =D4-AH4 -> -164 | AS4: =E4-AI4 -> -5 | AT4: =F4-AJ4 -> -27 | AU4: =G4-AK4 -> 5 | AV4: =H4-AL4 -> 7 | AW4: =I4-AM4 -> 4 | ... AY4: =K4-AO4 -> -51
A5: =A4+1 -> 3 | B5: =B3+20 -> 21 | C5: =C3+20 -> 22 | D5: =D3+20 -> 23 | E5: =E3+20 -> 24 | F5: =F3+20 -> 25 | G5: =G3+20 -> 26 | H5: =H3+20 -> 27 | I5: =I3+20 -> 28 | ... K5: =K3+20 -> 30 | L5: =INDEX('Draft Board'!$A$2:$AB$622,MATCH('Post-Mortem'!B5,'Draft Board'!$F$2:$F$622,0),3) -> Paulo Henrique | M5: =INDEX('Draft Board'!$A$2:$AB$622,MATCH('Post-Mortem'!C5,'Draft Board'!$F$2:$F$622,0),3) -> Lucho Acosta | N5: =INDEX('Draft Board'!$A$2:$AB$622,MATCH('Post-Mortem'!D5,'Draft Board'!$F$2:$F$622,0),3) -> Montoro | O5: =INDEX('Draft Board'!$A$2:$AB$622,MATCH('Post-Mortem'!E5,'Draft Board'!$F$2:$F$622,0),3) -> Kaiki Bruno | P5: =INDEX('Draft Board'!$A$2:$AB$622,MATCH('Post-Mortem'!F5,'Draft Board'!$F$2:$F$622,0),3) -> William | Q5: =INDEX('Draft Board'!$A$2:$AB$622,MATCH('Post-Mortem'!G5,'Draft Board'!$F$2:$F$622,0),3) -> Alex Telles | R5: =INDEX('Draft Board'!$A$2:$AB$622,MATCH('Post-Mortem'!H5,'Draft Board'!$F$2:$F$622,0),3) -> Gerson | S5: =INDEX('Draft Board'!$A$2:$AB$622,MATCH('Post-Mortem'!I5,'Draft Board'!$F$2:$F$622,0),3) -> Carrascal | ... U5: =INDEX('Draft Board'!$A$2:$AB$622,MATCH('Post-Mortem'!K5,'Draft Board'!$F$2:$F$622,0),3) -> Léo Pereira | V5: =INDEX('Draft Board'!$A$2:$AB$622,MATCH('Post-Mortem'!B5,'Draft Board'!$F$2:$F$622,0),21) -> S | W5: =INDEX('Draft Board'!$A$2:$AB$622,MATCH('Post-Mortem'!C5,'Draft Board'!$F$2:$F$622,0),21) -> A | X5: =INDEX('Draft Board'!$A$2:$AB$622,MATCH('Post-Mortem'!D5,'Draft Board'!$F$2:$F$622,0),21) -> B+ | Y5: =INDEX('Draft Board'!$A$2:$AB$622,MATCH('Post-Mortem'!E5,'Draft Board'!$F$2:$F$622,0),21) -> 0 | Z5: =INDEX('Draft Board'!$A$2:$AB$622,MATCH('Post-Mortem'!F5,'Draft Board'!$F$2:$F$622,0),21) -> S | AA5: =INDEX('Draft Board'!$A$2:$AB$622,MATCH('Post-Mortem'!G5,'Draft Board'!$F$2:$F$622,0),21) -> A | AB5: =INDEX('Draft Board'!$A$2:$AB$622,MATCH('Post-Mortem'!H5,'Draft Board'!$F$2:$F$622,0),21) -> B- | AC5: =INDEX('Draft Board'!$A$2:$AB$622,MATCH('Post-Mortem'!I5,'Draft Board'!$F$2:$F$622,0),21) -> A | ... AE5: =INDEX('Draft Board'!$A$2:$AB$622,MATCH('Post-Mortem'!K5,'Draft Board'!$F$2:$F$622,0),21) -> A | AF5: =INDEX('Draft Board'!$A$2:$AB$622,MATCH('Post-Mortem'!B5,'Draft Board'!$F$2:$F$622,0),22) -> 12 | AG5: =INDEX('Draft Board'!$A$2:$AB$622,MATCH('Post-Mortem'!C5,'Draft Board'!$F$2:$F$622,0),22) -> 34 | AH5: =INDEX('Draft Board'!$A$2:$AB$622,MATCH('Post-Mortem'!D5,'Draft Board'!$F$2:$F$622,0),22) -> 64 | AI5: =INDEX('Draft Board'!$A$2:$AB$622,MATCH('Post-Mortem'!E5,'Draft Board'!$F$2:$F$622,0),22) -> 0 | AJ5: =INDEX('Draft Board'!$A$2:$AB$622,MATCH('Post-Mortem'!F5,'Draft Board'!$F$2:$F$622,0),22) -> 13 | AK5: =INDEX('Draft Board'!$A$2:$AB$622,MATCH('Post-Mortem'!G5,'Draft Board'!$F$2:$F$622,0),22) -> 36 | AL5: =INDEX('Draft Board'!$A$2:$AB$622,MATCH('Post-Mortem'!H5,'Draft Board'!$F$2:$F$622,0),22) -> 105 | AM5: =INDEX('Draft Board'!$A$2:$AB$622,MATCH('Post-Mortem'!I5,'Draft Board'!$F$2:$F$622,0),22) -> 35 | ... AO5: =INDEX('Draft Board'!$A$2:$AB$622,MATCH('Post-Mortem'!K5,'Draft Board'!$F$2:$F$622,0),22) -> 38 | AP5: =B5-AF5 -> 9 | AQ5: =C5-AG5 -> -12 | AR5: =D5-AH5 -> -41 | AS5: =E5-AI5 -> 24 | AT5: =F5-AJ5 -> 12 | AU5: =G5-AK5 -> -10 | AV5: =H5-AL5 -> -78 | AW5: =I5-AM5 -> -7 | ... AY5: =K5-AO5 -> -8
A6: =A5+1 -> 4 | B6: =B4+20 -> 40 | C6: =C4+20 -> 39 | D6: =D4+20 -> 38 | E6: =E4+20 -> 37 | F6: =F4+20 -> 36 | G6: =G4+20 -> 35 | H6: =H4+20 -> 34 | I6: =I4+20 -> 33 | ... K6: =K4+20 -> 31 | L6: =INDEX('Draft Board'!$A$2:$AB$622,MATCH('Post-Mortem'!B6,'Draft Board'!$F$2:$F$622,0),3) -> Luciano Juba | M6: =INDEX('Draft Board'!$A$2:$AB$622,MATCH('Post-Mortem'!C6,'Draft Board'!$F$2:$F$622,0),3) -> Viveros | N6: =INDEX('Draft Board'!$A$2:$AB$622,MATCH('Post-Mortem'!D6,'Draft Board'!$F$2:$F$622,0),3) -> Plata | O6: =INDEX('Draft Board'!$A$2:$AB$622,MATCH('Post-Mortem'!E6,'Draft Board'!$F$2:$F$622,0),3) -> Rossi | P6: =INDEX('Draft Board'!$A$2:$AB$622,MATCH('Post-Mortem'!F6,'Draft Board'!$F$2:$F$622,0),3) -> Jemmes | Q6: =INDEX('Draft Board'!$A$2:$AB$622,MATCH('Post-Mortem'!G6,'Draft Board'!$F$2:$F$622,0),3) -> Erick Pulga | R6: =INDEX('Draft Board'!$A$2:$AB$622,MATCH('Post-Mortem'!H6,'Draft Board'!$F$2:$F$622,0),3) -> Martinelli | S6: =INDEX('Draft Board'!$A$2:$AB$622,MATCH('Post-Mortem'!I6,'Draft Board'!$F$2:$F$622,0),3) -> Borré | ... U6: =INDEX('Draft Board'!$A$2:$AB$622,MATCH('Post-Mortem'!K6,'Draft Board'!$F$2:$F$622,0),3) -> Alex Sandro | V6: =INDEX('Draft Board'!$A$2:$AB$622,MATCH('Post-Mortem'!B6,'Draft Board'!$F$2:$F$622,0),21) -> S- | W6: =INDEX('Draft Board'!$A$2:$AB$622,MATCH('Post-Mortem'!C6,'Draft Board'!$F$2:$F$622,0),21) -> A- | X6: =INDEX('Draft Board'!$A$2:$AB$622,MATCH('Post-Mortem'!D6,'Draft Board'!$F$2:$F$622,0),21) -> D+ | Y6: =INDEX('Draft Board'!$A$2:$AB$622,MATCH('Post-Mortem'!E6,'Draft Board'!$F$2:$F$622,0),21) -> S- | Z6: =INDEX('Draft Board'!$A$2:$AB$622,MATCH('Post-Mortem'!F6,'Draft Board'!$F$2:$F$622,0),21) -> A- | AA6: =INDEX('Draft Board'!$A$2:$AB$622,MATCH('Post-Mortem'!G6,'Draft Board'!$F$2:$F$622,0),21) -> A+ | AB6: =INDEX('Draft Board'!$A$2:$AB$622,MATCH('Post-Mortem'!H6,'Draft Board'!$F$2:$F$622,0),21) -> C- | AC6: =INDEX('Draft Board'!$A$2:$AB$622,MATCH('Post-Mortem'!I6,'Draft Board'!$F$2:$F$622,0),21) -> C+ | ... AE6: =INDEX('Draft Board'!$A$2:$AB$622,MATCH('Post-Mortem'!K6,'Draft Board'!$F$2:$F$622,0),21) -> C | AF6: =INDEX('Draft Board'!$A$2:$AB$622,MATCH('Post-Mortem'!B6,'Draft Board'!$F$2:$F$622,0),22) -> 17 | AG6: =INDEX('Draft Board'!$A$2:$AB$622,MATCH('Post-Mortem'!C6,'Draft Board'!$F$2:$F$622,0),22) -> 57 | AH6: =INDEX('Draft Board'!$A$2:$AB$622,MATCH('Post-Mortem'!D6,'Draft Board'!$F$2:$F$622,0),22) -> 231 | AI6: =INDEX('Draft Board'!$A$2:$AB$622,MATCH('Post-Mortem'!E6,'Draft Board'!$F$2:$F$622,0),22) -> 15 | AJ6: =INDEX('Draft Board'!$A$2:$AB$622,MATCH('Post-Mortem'!F6,'Draft Board'!$F$2:$F$622,0),22) -> 58 | AK6: =INDEX('Draft Board'!$A$2:$AB$622,MATCH('Post-Mortem'!G6,'Draft Board'!$F$2:$F$622,0),22) -> 24 | AL6: =INDEX('Draft Board'!$A$2:$AB$622,MATCH('Post-Mortem'!H6,'Draft Board'!$F$2:$F$622,0),22) -> 212 | AM6: =INDEX('Draft Board'!$A$2:$AB$622,MATCH('Post-Mortem'!I6,'Draft Board'!$F$2:$F$622,0),22) -> 126 | ... AO6: =INDEX('Draft Board'!$A$2:$AB$622,MATCH('Post-Mortem'!K6,'Draft Board'!$F$2:$F$622,0),22) -> 160 | AP6: =B6-AF6 -> 23 | AQ6: =C6-AG6 -> -18 | AR6: =D6-AH6 -> -193 | AS6: =E6-AI6 -> 22 | AT6: =F6-AJ6 -> -22 | AU6: =G6-AK6 -> 11 | AV6: =H6-AL6 -> -178 | AW6: =I6-AM6 -> -93 | ... AY6: =K6-AO6 -> -129
A7: =A6+1 -> 5 | B7: =B5+20 -> 41 | C7: =C5+20 -> 42 | D7: =D5+20 -> 43 | E7: =E5+20 -> 44 | F7: =F5+20 -> 45 | G7: =G5+20 -> 46 | H7: =H5+20 -> 47 | I7: =I5+20 -> 48 | ... K7: =K5+20 -> 50 | L7: =INDEX('Draft Board'!$A$2:$AB$622,MATCH('Post-Mortem'!B7,'Draft Board'!$F$2:$F$622,0),3) -> Carlos Miguel | M7: =INDEX('Draft Board'!$A$2:$AB$622,MATCH('Post-Mortem'!C7,'Draft Board'!$F$2:$F$622,0),3) -> Eduardo Sasha | N7: =INDEX('Draft Board'!$A$2:$AB$622,MATCH('Post-Mortem'!D7,'Draft Board'!$F$2:$F$622,0),3) -> Serna | O7: =INDEX('Draft Board'!$A$2:$AB$622,MATCH('Post-Mortem'!E7,'Draft Board'!$F$2:$F$622,0),3) -> Samuel Xavier | P7: =INDEX('Draft Board'!$A$2:$AB$622,MATCH('Post-Mortem'!F7,'Draft Board'!$F$2:$F$622,0),3) -> Cássio | Q7: =INDEX('Draft Board'!$A$2:$AB$622,MATCH('Post-Mortem'!G7,'Draft Board'!$F$2:$F$622,0),3) -> Canobbio | R7: =INDEX('Draft Board'!$A$2:$AB$622,MATCH('Post-Mortem'!H7,'Draft Board'!$F$2:$F$622,0),3) -> Alexander Barboza | S7: =INDEX('Draft Board'!$A$2:$AB$622,MATCH('Post-Mortem'!I7,'Draft Board'!$F$2:$F$622,0),3) -> Renan Lodi | ... U7: =INDEX('Draft Board'!$A$2:$AB$622,MATCH('Post-Mortem'!K7,'Draft Board'!$F$2:$F$622,0),3) -> Fábio | V7: =INDEX('Draft Board'!$A$2:$AB$622,MATCH('Post-Mortem'!B7,'Draft Board'!$F$2:$F$622,0),21) -> S- | W7: =INDEX('Draft Board'!$A$2:$AB$622,MATCH('Post-Mortem'!C7,'Draft Board'!$F$2:$F$622,0),21) -> B | X7: =INDEX('Draft Board'!$A$2:$AB$622,MATCH('Post-Mortem'!D7,'Draft Board'!$F$2:$F$622,0),21) -> A+ | Y7: =INDEX('Draft Board'!$A$2:$AB$622,MATCH('Post-Mortem'!E7,'Draft Board'!$F$2:$F$622,0),21) -> A | Z7: =INDEX('Draft Board'!$A$2:$AB$622,MATCH('Post-Mortem'!F7,'Draft Board'!$F$2:$F$622,0),21) -> S- | AA7: =INDEX('Draft Board'!$A$2:$AB$622,MATCH('Post-Mortem'!G7,'Draft Board'!$F$2:$F$622,0),21) -> A | AB7: =INDEX('Draft Board'!$A$2:$AB$622,MATCH('Post-Mortem'!H7,'Draft Board'!$F$2:$F$622,0),21) -> B+ | AC7: =INDEX('Draft Board'!$A$2:$AB$622,MATCH('Post-Mortem'!I7,'Draft Board'!$F$2:$F$622,0),21) -> A+ | ... AE7: =INDEX('Draft Board'!$A$2:$AB$622,MATCH('Post-Mortem'!K7,'Draft Board'!$F$2:$F$622,0),21) -> B- | AF7: =INDEX('Draft Board'!$A$2:$AB$622,MATCH('Post-Mortem'!B7,'Draft Board'!$F$2:$F$622,0),22) -> 19 | AG7: =INDEX('Draft Board'!$A$2:$AB$622,MATCH('Post-Mortem'!C7,'Draft Board'!$F$2:$F$622,0),22) -> 93 | AH7: =INDEX('Draft Board'!$A$2:$AB$622,MATCH('Post-Mortem'!D7,'Draft Board'!$F$2:$F$622,0),22) -> 28 | AI7: =INDEX('Draft Board'!$A$2:$AB$622,MATCH('Post-Mortem'!E7,'Draft Board'!$F$2:$F$622,0),22) -> 41 | AJ7: =INDEX('Draft Board'!$A$2:$AB$622,MATCH('Post-Mortem'!F7,'Draft Board'!$F$2:$F$622,0),22) -> 18 | AK7: =INDEX('Draft Board'!$A$2:$AB$622,MATCH('Post-Mortem'!G7,'Draft Board'!$F$2:$F$622,0),22) -> 29 | AL7: =INDEX('Draft Board'!$A$2:$AB$622,MATCH('Post-Mortem'!H7,'Draft Board'!$F$2:$F$622,0),22) -> 66 | AM7: =INDEX('Draft Board'!$A$2:$AB$622,MATCH('Post-Mortem'!I7,'Draft Board'!$F$2:$F$622,0),22) -> 27 | ... AO7: =INDEX('Draft Board'!$A$2:$AB$622,MATCH('Post-Mortem'!K7,'Draft Board'!$F$2:$F$622,0),22) -> 109 | AP7: =B7-AF7 -> 22 | AQ7: =C7-AG7 -> -51 | AR7: =D7-AH7 -> 15 | AS7: =E7-AI7 -> 3 | AT7: =F7-AJ7 -> 27 | AU7: =G7-AK7 -> 17 | AV7: =H7-AL7 -> -19 | AW7: =I7-AM7 -> 21 | ... AY7: =K7-AO7 -> -59
A8: =A7+1 -> 6 | B8: =B6+20 -> 60 | C8: =C6+20 -> 59 | D8: =D6+20 -> 58 | E8: =E6+20 -> 57 | F8: =F6+20 -> 56 | G8: =G6+20 -> 55 | H8: =H6+20 -> 54 | I8: =I6+20 -> 53 | ... K8: =K6+20 -> 51 | L8: =INDEX('Draft Board'!$A$2:$AB$622,MATCH('Post-Mortem'!B8,'Draft Board'!$F$2:$F$622,0),3) -> Fabrício Bruno | M8: =INDEX('Draft Board'!$A$2:$AB$622,MATCH('Post-Mortem'!C8,'Draft Board'!$F$2:$F$622,0),3) -> Walter | N8: =INDEX('Draft Board'!$A$2:$AB$622,MATCH('Post-Mortem'!D8,'Draft Board'!$F$2:$F$622,0),3) -> Santiago Rodríguez | O8: =INDEX('Draft Board'!$A$2:$AB$622,MATCH('Post-Mortem'!E8,'Draft Board'!$F$2:$F$622,0),3) -> Arboleda | P8: =INDEX('Draft Board'!$A$2:$AB$622,MATCH('Post-Mortem'!F8,'Draft Board'!$F$2:$F$622,0),3) -> Arthur Cabral | Q8: =INDEX('Draft Board'!$A$2:$AB$622,MATCH('Post-Mortem'!G8,'Draft Board'!$F$2:$F$622,0),3) -> Garro | R8: =INDEX('Draft Board'!$A$2:$AB$622,MATCH('Post-Mortem'!H8,'Draft Board'!$F$2:$F$622,0),3) -> Tetê | S8: =INDEX('Draft Board'!$A$2:$AB$622,MATCH('Post-Mortem'!I8,'Draft Board'!$F$2:$F$622,0),3) -> Juninho Capixaba | ... U8: =INDEX('Draft Board'!$A$2:$AB$622,MATCH('Post-Mortem'!K8,'Draft Board'!$F$2:$F$622,0),3) -> Piquerez | V8: =INDEX('Draft Board'!$A$2:$AB$622,MATCH('Post-Mortem'!B8,'Draft Board'!$F$2:$F$622,0),21) -> A | W8: =INDEX('Draft Board'!$A$2:$AB$622,MATCH('Post-Mortem'!C8,'Draft Board'!$F$2:$F$622,0),21) -> S- | X8: =INDEX('Draft Board'!$A$2:$AB$622,MATCH('Post-Mortem'!D8,'Draft Board'!$F$2:$F$622,0),21) -> B | Y8: =INDEX('Draft Board'!$A$2:$AB$622,MATCH('Post-Mortem'!E8,'Draft Board'!$F$2:$F$622,0),21) -> A | Z8: =INDEX('Draft Board'!$A$2:$AB$622,MATCH('Post-Mortem'!F8,'Draft Board'!$F$2:$F$622,0),21) -> C+ | AA8: =INDEX('Draft Board'!$A$2:$AB$622,MATCH('Post-Mortem'!G8,'Draft Board'!$F$2:$F$622,0),21) -> C+ | AB8: =INDEX('Draft Board'!$A$2:$AB$622,MATCH('Post-Mortem'!H8,'Draft Board'!$F$2:$F$622,0),21) -> B+ | AC8: =INDEX('Draft Board'!$A$2:$AB$622,MATCH('Post-Mortem'!I8,'Draft Board'!$F$2:$F$622,0),21) -> A | ... AE8: =INDEX('Draft Board'!$A$2:$AB$622,MATCH('Post-Mortem'!K8,'Draft Board'!$F$2:$F$622,0),21) -> A | AF8: =INDEX('Draft Board'!$A$2:$AB$622,MATCH('Post-Mortem'!B8,'Draft Board'!$F$2:$F$622,0),22) -> 39 | AG8: =INDEX('Draft Board'!$A$2:$AB$622,MATCH('Post-Mortem'!C8,'Draft Board'!$F$2:$F$622,0),22) -> 20 | AH8: =INDEX('Draft Board'!$A$2:$AB$622,MATCH('Post-Mortem'!D8,'Draft Board'!$F$2:$F$622,0),22) -> 99 | AI8: =INDEX('Draft Board'!$A$2:$AB$622,MATCH('Post-Mortem'!E8,'Draft Board'!$F$2:$F$622,0),22) -> 46 | AJ8: =INDEX('Draft Board'!$A$2:$AB$622,MATCH('Post-Mortem'!F8,'Draft Board'!$F$2:$F$622,0),22) -> 125 | AK8: =INDEX('Draft Board'!$A$2:$AB$622,MATCH('Post-Mortem'!G8,'Draft Board'!$F$2:$F$622,0),22) -> 139 | AL8: =INDEX('Draft Board'!$A$2:$AB$622,MATCH('Post-Mortem'!H8,'Draft Board'!$F$2:$F$622,0),22) -> 69 | AM8: =INDEX('Draft Board'!$A$2:$AB$622,MATCH('Post-Mortem'!I8,'Draft Board'!$F$2:$F$622,0),22) -> 32 | ... AO8: =INDEX('Draft Board'!$A$2:$AB$622,MATCH('Post-Mortem'!K8,'Draft Board'!$F$2:$F$622,0),22) -> 31 | AP8: =B8-AF8 -> 21 | AQ8: =C8-AG8 -> 39 | AR8: =D8-AH8 -> -41 | AS8: =E8-AI8 -> 11 | AT8: =F8-AJ8 -> -69 | AU8: =G8-AK8 -> -84 | AV8: =H8-AL8 -> -15 | AW8: =I8-AM8 -> 21 | ... AY8: =K8-AO8 -> 20
A9: =A8+1 -> 7 | B9: =B7+20 -> 61 | C9: =C7+20 -> 62 | D9: =D7+20 -> 63 | E9: =E7+20 -> 64 | F9: =F7+20 -> 65 | G9: =G7+20 -> 66 | H9: =H7+20 -> 67 | I9: =I7+20 -> 68 | ... K9: =K7+20 -> 70 | L9: =INDEX('Draft Board'!$A$2:$AB$622,MATCH('Post-Mortem'!B9,'Draft Board'!$F$2:$F$622,0),3) -> Erick | M9: =INDEX('Draft Board'!$A$2:$AB$622,MATCH('Post-Mortem'!C9,'Draft Board'!$F$2:$F$622,0),3) -> Alesson | N9: =INDEX('Draft Board'!$A$2:$AB$622,MATCH('Post-Mortem'!D9,'Draft Board'!$F$2:$F$622,0),3) -> Léo Jardim | O9: =INDEX('Draft Board'!$A$2:$AB$622,MATCH('Post-Mortem'!E9,'Draft Board'!$F$2:$F$622,0),3) -> Philippe Coutinho | P9: =INDEX('Draft Board'!$A$2:$AB$622,MATCH('Post-Mortem'!F9,'Draft Board'!$F$2:$F$622,0),3) -> Maurício | Q9: =INDEX('Draft Board'!$A$2:$AB$622,MATCH('Post-Mortem'!G9,'Draft Board'!$F$2:$F$622,0),3) -> Gustavo Scarpa | R9: =INDEX('Draft Board'!$A$2:$AB$622,MATCH('Post-Mortem'!H9,'Draft Board'!$F$2:$F$622,0),3) -> Everson | S9: =INDEX('Draft Board'!$A$2:$AB$622,MATCH('Post-Mortem'!I9,'Draft Board'!$F$2:$F$622,0),3) -> Varela | ... U9: =INDEX('Draft Board'!$A$2:$AB$622,MATCH('Post-Mortem'!K9,'Draft Board'!$F$2:$F$622,0),3) -> Luiz Araújo | V9: =INDEX('Draft Board'!$A$2:$AB$622,MATCH('Post-Mortem'!B9,'Draft Board'!$F$2:$F$622,0),21) -> A | W9: =INDEX('Draft Board'!$A$2:$AB$622,MATCH('Post-Mortem'!C9,'Draft Board'!$F$2:$F$622,0),21) -> B+ | X9: =INDEX('Draft Board'!$A$2:$AB$622,MATCH('Post-Mortem'!D9,'Draft Board'!$F$2:$F$622,0),21) -> C- | Y9: =INDEX('Draft Board'!$A$2:$AB$622,MATCH('Post-Mortem'!E9,'Draft Board'!$F$2:$F$622,0),21) -> B+ | Z9: =INDEX('Draft Board'!$A$2:$AB$622,MATCH('Post-Mortem'!F9,'Draft Board'!$F$2:$F$622,0),21) -> B- | AA9: =INDEX('Draft Board'!$A$2:$AB$622,MATCH('Post-Mortem'!G9,'Draft Board'!$F$2:$F$622,0),21) -> C+ | AB9: =INDEX('Draft Board'!$A$2:$AB$622,MATCH('Post-Mortem'!H9,'Draft Board'!$F$2:$F$622,0),21) -> B | AC9: =INDEX('Draft Board'!$A$2:$AB$622,MATCH('Post-Mortem'!I9,'Draft Board'!$F$2:$F$622,0),21) -> B- | ... AE9: =INDEX('Draft Board'!$A$2:$AB$622,MATCH('Post-Mortem'!K9,'Draft Board'!$F$2:$F$622,0),21) -> B | AF9: =INDEX('Draft Board'!$A$2:$AB$622,MATCH('Post-Mortem'!B9,'Draft Board'!$F$2:$F$622,0),22) -> 44 | AG9: =INDEX('Draft Board'!$A$2:$AB$622,MATCH('Post-Mortem'!C9,'Draft Board'!$F$2:$F$622,0),22) -> 76 | AH9: =INDEX('Draft Board'!$A$2:$AB$622,MATCH('Post-Mortem'!D9,'Draft Board'!$F$2:$F$622,0),22) -> 192 | AI9: =INDEX('Draft Board'!$A$2:$AB$622,MATCH('Post-Mortem'!E9,'Draft Board'!$F$2:$F$622,0),22) -> 84 | AJ9: =INDEX('Draft Board'!$A$2:$AB$622,MATCH('Post-Mortem'!F9,'Draft Board'!$F$2:$F$622,0),22) -> 108 | AK9: =INDEX('Draft Board'!$A$2:$AB$622,MATCH('Post-Mortem'!G9,'Draft Board'!$F$2:$F$622,0),22) -> 140 | AL9: =INDEX('Draft Board'!$A$2:$AB$622,MATCH('Post-Mortem'!H9,'Draft Board'!$F$2:$F$622,0),22) -> 87 | AM9: =INDEX('Draft Board'!$A$2:$AB$622,MATCH('Post-Mortem'!I9,'Draft Board'!$F$2:$F$622,0),22) -> 113 | ... AO9: =INDEX('Draft Board'!$A$2:$AB$622,MATCH('Post-Mortem'!K9,'Draft Board'!$F$2:$F$622,0),22) -> 91 | AP9: =B9-AF9 -> 17 | AQ9: =C9-AG9 -> -14 | AR9: =D9-AH9 -> -129 | AS9: =E9-AI9 -> -20 | AT9: =F9-AJ9 -> -43 | AU9: =G9-AK9 -> -74 | AV9: =H9-AL9 -> -20 | AW9: =I9-AM9 -> -45 | ... AY9: =K9-AO9 -> -21
A10: =A9+1 -> 8 | B10: =B8+20 -> 80 | C10: =C8+20 -> 79 | D10: =D8+20 -> 78 | E10: =E8+20 -> 77 | F10: =F8+20 -> 76 | G10: =G8+20 -> 75 | H10: =H8+20 -> 74 | I10: =I8+20 -> 73 | ... K10: =K8+20 -> 71 | L10: =INDEX('Draft Board'!$A$2:$AB$622,MATCH('Post-Mortem'!B10,'Draft Board'!$F$2:$F$622,0),3) -> Lucas Romero | M10: =INDEX('Draft Board'!$A$2:$AB$622,MATCH('Post-Mortem'!C10,'Draft Board'!$F$2:$F$622,0),3) -> Bernabéi | N10: =INDEX('Draft Board'!$A$2:$AB$622,MATCH('Post-Mortem'!D10,'Draft Board'!$F$2:$F$622,0),3) -> Gustavo Henrique | O10: =INDEX('Draft Board'!$A$2:$AB$622,MATCH('Post-Mortem'!E10,'Draft Board'!$F$2:$F$622,0),3) -> Felipe Anderson | P10: =INDEX('Draft Board'!$A$2:$AB$622,MATCH('Post-Mortem'!F10,'Draft Board'!$F$2:$F$622,0),3) -> Renato Kayzer | Q10: =INDEX('Draft Board'!$A$2:$AB$622,MATCH('Post-Mortem'!G10,'Draft Board'!$F$2:$F$622,0),3) -> Villalba | R10: =INDEX('Draft Board'!$A$2:$AB$622,MATCH('Post-Mortem'!H10,'Draft Board'!$F$2:$F$622,0),3) -> Guilherme Arana | S10: =INDEX('Draft Board'!$A$2:$AB$622,MATCH('Post-Mortem'!I10,'Draft Board'!$F$2:$F$622,0),3) -> Gustavo Gómez | ... U10: =INDEX('Draft Board'!$A$2:$AB$622,MATCH('Post-Mortem'!K10,'Draft Board'!$F$2:$F$622,0),3) -> Andreas Pereira | V10: =INDEX('Draft Board'!$A$2:$AB$622,MATCH('Post-Mortem'!B10,'Draft Board'!$F$2:$F$622,0),21) -> B+ | W10: =INDEX('Draft Board'!$A$2:$AB$622,MATCH('Post-Mortem'!C10,'Draft Board'!$F$2:$F$622,0),21) -> A- | X10: =INDEX('Draft Board'!$A$2:$AB$622,MATCH('Post-Mortem'!D10,'Draft Board'!$F$2:$F$622,0),21) -> C+ | Y10: =INDEX('Draft Board'!$A$2:$AB$622,MATCH('Post-Mortem'!E10,'Draft Board'!$F$2:$F$622,0),21) -> 0 | Z10: =INDEX('Draft Board'!$A$2:$AB$622,MATCH('Post-Mortem'!F10,'Draft Board'!$F$2:$F$622,0),21) -> B+ | AA10: =INDEX('Draft Board'!$A$2:$AB$622,MATCH('Post-Mortem'!G10,'Draft Board'!$F$2:$F$622,0),21) -> A- | AB10: =INDEX('Draft Board'!$A$2:$AB$622,MATCH('Post-Mortem'!H10,'Draft Board'!$F$2:$F$622,0),21) -> C+ | AC10: =INDEX('Draft Board'!$A$2:$AB$622,MATCH('Post-Mortem'!I10,'Draft Board'!$F$2:$F$622,0),21) -> A- | ... AE10: =INDEX('Draft Board'!$A$2:$AB$622,MATCH('Post-Mortem'!K10,'Draft Board'!$F$2:$F$622,0),21) -> C | AF10: =INDEX('Draft Board'!$A$2:$AB$622,MATCH('Post-Mortem'!B10,'Draft Board'!$F$2:$F$622,0),22) -> 73 | AG10: =INDEX('Draft Board'!$A$2:$AB$622,MATCH('Post-Mortem'!C10,'Draft Board'!$F$2:$F$622,0),22) -> 48 | AH10: =INDEX('Draft Board'!$A$2:$AB$622,MATCH('Post-Mortem'!D10,'Draft Board'!$F$2:$F$622,0),22) -> 127 | AI10: =INDEX('Draft Board'!$A$2:$AB$622,MATCH('Post-Mortem'!E10,'Draft Board'!$F$2:$F$622,0),22) -> 0 | AJ10: =INDEX('Draft Board'!$A$2:$AB$622,MATCH('Post-Mortem'!F10,'Draft Board'!$F$2:$F$622,0),22) -> 79 | AK10: =INDEX('Draft Board'!$A$2:$AB$622,MATCH('Post-Mortem'!G10,'Draft Board'!$F$2:$F$622,0),22) -> 49 | AL10: =INDEX('Draft Board'!$A$2:$AB$622,MATCH('Post-Mortem'!H10,'Draft Board'!$F$2:$F$622,0),22) -> 135 | AM10: =INDEX('Draft Board'!$A$2:$AB$622,MATCH('Post-Mortem'!I10,'Draft Board'!$F$2:$F$622,0),22) -> 59 | ... AO10: =INDEX('Draft Board'!$A$2:$AB$622,MATCH('Post-Mortem'!K10,'Draft Board'!$F$2:$F$622,0),22) -> 185 | AP10: =B10-AF10 -> 7 | AQ10: =C10-AG10 -> 31 | AR10: =D10-AH10 -> -49 | AS10: =E10-AI10 -> 77 | AT10: =F10-AJ10 -> -3 | AU10: =G10-AK10 -> 26 | AV10: =H10-AL10 -> -61 | AW10: =I10-AM10 -> 14 | ... AY10: =K10-AO10 -> -114
A11: =A10+1 -> 9 | B11: =B9+20 -> 81 | C11: =C9+20 -> 82 | D11: =D9+20 -> 83 | E11: =E9+20 -> 84 | F11: =F9+20 -> 85 | G11: =G9+20 -> 86 | H11: =H9+20 -> 87 | I11: =I9+20 -> 88 | ... K11: =K9+20 -> 90 | L11: =INDEX('Draft Board'!$A$2:$AB$622,MATCH('Post-Mortem'!B11,'Draft Board'!$F$2:$F$622,0),3) -> Jean Lucas | M11: =INDEX('Draft Board'!$A$2:$AB$622,MATCH('Post-Mortem'!C11,'Draft Board'!$F$2:$F$622,0),3) -> Enzo Díaz | N11: =INDEX('Draft Board'!$A$2:$AB$622,MATCH('Post-Mortem'!D11,'Draft Board'!$F$2:$F$622,0),3) -> Vitão | O11: =INDEX('Draft Board'!$A$2:$AB$622,MATCH('Post-Mortem'!E11,'Draft Board'!$F$2:$F$622,0),3) -> Murilo | P11: =INDEX('Draft Board'!$A$2:$AB$622,MATCH('Post-Mortem'!F11,'Draft Board'!$F$2:$F$622,0),3) -> Arthur Melo | Q11: =INDEX('Draft Board'!$A$2:$AB$622,MATCH('Post-Mortem'!G11,'Draft Board'!$F$2:$F$622,0),3) -> Savarino | R11: =INDEX('Draft Board'!$A$2:$AB$622,MATCH('Post-Mortem'!H11,'Draft Board'!$F$2:$F$622,0),3) -> André Ramalho | S11: =INDEX('Draft Board'!$A$2:$AB$622,MATCH('Post-Mortem'!I11,'Draft Board'!$F$2:$F$622,0),3) -> Léo Linck | ... U11: =INDEX('Draft Board'!$A$2:$AB$622,MATCH('Post-Mortem'!K11,'Draft Board'!$F$2:$F$622,0),3) -> Everton Ribeiro | V11: =INDEX('Draft Board'!$A$2:$AB$622,MATCH('Post-Mortem'!B11,'Draft Board'!$F$2:$F$622,0),21) -> B+ | W11: =INDEX('Draft Board'!$A$2:$AB$622,MATCH('Post-Mortem'!C11,'Draft Board'!$F$2:$F$622,0),21) -> S- | X11: =INDEX('Draft Board'!$A$2:$AB$622,MATCH('Post-Mortem'!D11,'Draft Board'!$F$2:$F$622,0),21) -> D+ | Y11: =INDEX('Draft Board'!$A$2:$AB$622,MATCH('Post-Mortem'!E11,'Draft Board'!$F$2:$F$622,0),21) -> C | Z11: =INDEX('Draft Board'!$A$2:$AB$622,MATCH('Post-Mortem'!F11,'Draft Board'!$F$2:$F$622,0),21) -> B- | AA11: =INDEX('Draft Board'!$A$2:$AB$622,MATCH('Post-Mortem'!G11,'Draft Board'!$F$2:$F$622,0),21) -> C+ | AB11: =INDEX('Draft Board'!$A$2:$AB$622,MATCH('Post-Mortem'!H11,'Draft Board'!$F$2:$F$622,0),21) -> C | AC11: =INDEX('Draft Board'!$A$2:$AB$622,MATCH('Post-Mortem'!I11,'Draft Board'!$F$2:$F$622,0),21) -> D | ... AE11: =INDEX('Draft Board'!$A$2:$AB$622,MATCH('Post-Mortem'!K11,'Draft Board'!$F$2:$F$622,0),21) -> B- | AF11: =INDEX('Draft Board'!$A$2:$AB$622,MATCH('Post-Mortem'!B11,'Draft Board'!$F$2:$F$622,0),22) -> 77 | AG11: =INDEX('Draft Board'!$A$2:$AB$622,MATCH('Post-Mortem'!C11,'Draft Board'!$F$2:$F$622,0),22) -> 16 | AH11: =INDEX('Draft Board'!$A$2:$AB$622,MATCH('Post-Mortem'!D11,'Draft Board'!$F$2:$F$622,0),22) -> 236 | AI11: =INDEX('Draft Board'!$A$2:$AB$622,MATCH('Post-Mortem'!E11,'Draft Board'!$F$2:$F$622,0),22) -> 171 | AJ11: =INDEX('Draft Board'!$A$2:$AB$622,MATCH('Post-Mortem'!F11,'Draft Board'!$F$2:$F$622,0),22) -> 123 | AK11: =INDEX('Draft Board'!$A$2:$AB$622,MATCH('Post-Mortem'!G11,'Draft Board'!$F$2:$F$622,0),22) -> 132 | AL11: =INDEX('Draft Board'!$A$2:$AB$622,MATCH('Post-Mortem'!H11,'Draft Board'!$F$2:$F$622,0),22) -> 165 | AM11: =INDEX('Draft Board'!$A$2:$AB$622,MATCH('Post-Mortem'!I11,'Draft Board'!$F$2:$F$622,0),22) -> 256 | ... AO11: =INDEX('Draft Board'!$A$2:$AB$622,MATCH('Post-Mortem'!K11,'Draft Board'!$F$2:$F$622,0),22) -> 120 | AP11: =B11-AF11 -> 4 | AQ11: =C11-AG11 -> 66 | AR11: =D11-AH11 -> -153 | AS11: =E11-AI11 -> -87 | AT11: =F11-AJ11 -> -38 | AU11: =G11-AK11 -> -46 | AV11: =H11-AL11 -> -78 | AW11: =I11-AM11 -> -168 | ... AY11: =K11-AO11 -> -30
A12: =A11+1 -> 10 | B12: =B10+20 -> 100 | C12: =C10+20 -> 99 | D12: =D10+20 -> 98 | E12: =E10+20 -> 97 | F12: =F10+20 -> 96 | G12: =G10+20 -> 95 | H12: =H10+20 -> 94 | I12: =I10+20 -> 93 | ... K12: =K10+20 -> 91 | L12: =INDEX('Draft Board'!$A$2:$AB$622,MATCH('Post-Mortem'!B12,'Draft Board'!$F$2:$F$622,0),3) -> Vitinho | M12: =INDEX('Draft Board'!$A$2:$AB$622,MATCH('Post-Mortem'!C12,'Draft Board'!$F$2:$F$622,0),3) -> Khellven | N12: =INDEX('Draft Board'!$A$2:$AB$622,MATCH('Post-Mortem'!D12,'Draft Board'!$F$2:$F$622,0),3) -> Gilberto | O12: =INDEX('Draft Board'!$A$2:$AB$622,MATCH('Post-Mortem'!E12,'Draft Board'!$F$2:$F$622,0),3) -> Bruno Henrique | P12: =INDEX('Draft Board'!$A$2:$AB$622,MATCH('Post-Mortem'!F12,'Draft Board'!$F$2:$F$622,0),3) -> Matheuzinho | Q12: =INDEX('Draft Board'!$A$2:$AB$622,MATCH('Post-Mortem'!G12,'Draft Board'!$F$2:$F$622,0),3) -> Zapelli | R12: =INDEX('Draft Board'!$A$2:$AB$622,MATCH('Post-Mortem'!H12,'Draft Board'!$F$2:$F$622,0),3) -> Carbonero | S12: =INDEX('Draft Board'!$A$2:$AB$622,MATCH('Post-Mortem'!I12,'Draft Board'!$F$2:$F$622,0),3) -> Artur | ... U12: =INDEX('Draft Board'!$A$2:$AB$622,MATCH('Post-Mortem'!K12,'Draft Board'!$F$2:$F$622,0),3) -> Lucas Moura | V12: =INDEX('Draft Board'!$A$2:$AB$622,MATCH('Post-Mortem'!B12,'Draft Board'!$F$2:$F$622,0),21) -> A+ | W12: =INDEX('Draft Board'!$A$2:$AB$622,MATCH('Post-Mortem'!C12,'Draft Board'!$F$2:$F$622,0),21) -> A | X12: =INDEX('Draft Board'!$A$2:$AB$622,MATCH('Post-Mortem'!D12,'Draft Board'!$F$2:$F$622,0),21) -> C | Y12: =INDEX('Draft Board'!$A$2:$AB$622,MATCH('Post-Mortem'!E12,'Draft Board'!$F$2:$F$622,0),21) -> D+ | Z12: =INDEX('Draft Board'!$A$2:$AB$622,MATCH('Post-Mortem'!F12,'Draft Board'!$F$2:$F$622,0),21) -> A+ | AA12: =INDEX('Draft Board'!$A$2:$AB$622,MATCH('Post-Mortem'!G12,'Draft Board'!$F$2:$F$622,0),21) -> C+ | AB12: =INDEX('Draft Board'!$A$2:$AB$622,MATCH('Post-Mortem'!H12,'Draft Board'!$F$2:$F$622,0),21) -> B+ | AC12: =INDEX('Draft Board'!$A$2:$AB$622,MATCH('Post-Mortem'!I12,'Draft Board'!$F$2:$F$622,0),21) -> B- | ... AE12: =INDEX('Draft Board'!$A$2:$AB$622,MATCH('Post-Mortem'!K12,'Draft Board'!$F$2:$F$622,0),21) -> C | AF12: =INDEX('Draft Board'!$A$2:$AB$622,MATCH('Post-Mortem'!B12,'Draft Board'!$F$2:$F$622,0),22) -> 26 | AG12: =INDEX('Draft Board'!$A$2:$AB$622,MATCH('Post-Mortem'!C12,'Draft Board'!$F$2:$F$622,0),22) -> 45 | AH12: =INDEX('Draft Board'!$A$2:$AB$622,MATCH('Post-Mortem'!D12,'Draft Board'!$F$2:$F$622,0),22) -> 150 | AI12: =INDEX('Draft Board'!$A$2:$AB$622,MATCH('Post-Mortem'!E12,'Draft Board'!$F$2:$F$622,0),22) -> 227 | AJ12: =INDEX('Draft Board'!$A$2:$AB$622,MATCH('Post-Mortem'!F12,'Draft Board'!$F$2:$F$622,0),22) -> 21 | AK12: =INDEX('Draft Board'!$A$2:$AB$622,MATCH('Post-Mortem'!G12,'Draft Board'!$F$2:$F$622,0),22) -> 142 | AL12: =INDEX('Draft Board'!$A$2:$AB$622,MATCH('Post-Mortem'!H12,'Draft Board'!$F$2:$F$622,0),22) -> 78 | AM12: =INDEX('Draft Board'!$A$2:$AB$622,MATCH('Post-Mortem'!I12,'Draft Board'!$F$2:$F$622,0),22) -> 116 | ... AO12: =INDEX('Draft Board'!$A$2:$AB$622,MATCH('Post-Mortem'!K12,'Draft Board'!$F$2:$F$622,0),22) -> 147 | AP12: =B12-AF12 -> 74 | AQ12: =C12-AG12 -> 54 | AR12: =D12-AH12 -> -52 | AS12: =E12-AI12 -> -130 | AT12: =F12-AJ12 -> 75 | AU12: =G12-AK12 -> -47 | AV12: =H12-AL12 -> 16 | AW12: =I12-AM12 -> -23 | ... AY12: =K12-AO12 -> -56
A13: =A12+1 -> 11 | B13: =B11+20 -> 101 | C13: =C11+20 -> 102 | D13: =D11+20 -> 103 | E13: =E11+20 -> 104 | F13: =F11+20 -> 105 | G13: =G11+20 -> 106 | H13: =H11+20 -> 107 | I13: =I11+20 -> 108 | ... K13: =K11+20 -> 110 | L13: =INDEX('Draft Board'!$A$2:$AB$622,MATCH('Post-Mortem'!B13,'Draft Board'!$F$2:$F$622,0),3) -> Lucas Barbosa | M13: =INDEX('Draft Board'!$A$2:$AB$622,MATCH('Post-Mortem'!C13,'Draft Board'!$F$2:$F$622,0),3) -> Andrés Gómez | N13: =INDEX('Draft Board'!$A$2:$AB$622,MATCH('Post-Mortem'!D13,'Draft Board'!$F$2:$F$622,0),3) -> Igor Vinícius | O13: =INDEX('Draft Board'!$A$2:$AB$622,MATCH('Post-Mortem'!E13,'Draft Board'!$F$2:$F$622,0),3) -> Neto | P13: =INDEX('Draft Board'!$A$2:$AB$622,MATCH('Post-Mortem'!F13,'Draft Board'!$F$2:$F$622,0),3) -> Santiago Mingo | Q13: =INDEX('Draft Board'!$A$2:$AB$622,MATCH('Post-Mortem'!G13,'Draft Board'!$F$2:$F$622,0),3) -> Rollheiser | R13: =INDEX('Draft Board'!$A$2:$AB$622,MATCH('Post-Mortem'!H13,'Draft Board'!$F$2:$F$622,0),3) -> Marlon Freitas | S13: =INDEX('Draft Board'!$A$2:$AB$622,MATCH('Post-Mortem'!I13,'Draft Board'!$F$2:$F$622,0),3) -> Junior Alonso | ... U13: =INDEX('Draft Board'!$A$2:$AB$622,MATCH('Post-Mortem'!K13,'Draft Board'!$F$2:$F$622,0),3) -> Wagner Leonardo | V13: =INDEX('Draft Board'!$A$2:$AB$622,MATCH('Post-Mortem'!B13,'Draft Board'!$F$2:$F$622,0),21) -> A- | W13: =INDEX('Draft Board'!$A$2:$AB$622,MATCH('Post-Mortem'!C13,'Draft Board'!$F$2:$F$622,0),21) -> B+ | X13: =INDEX('Draft Board'!$A$2:$AB$622,MATCH('Post-Mortem'!D13,'Draft Board'!$F$2:$F$622,0),21) -> B- | Y13: =INDEX('Draft Board'!$A$2:$AB$622,MATCH('Post-Mortem'!E13,'Draft Board'!$F$2:$F$622,0),21) -> C- | Z13: =INDEX('Draft Board'!$A$2:$AB$622,MATCH('Post-Mortem'!F13,'Draft Board'!$F$2:$F$622,0),21) -> D+ | AA13: =INDEX('Draft Board'!$A$2:$AB$622,MATCH('Post-Mortem'!G13,'Draft Board'!$F$2:$F$622,0),21) -> C | AB13: =INDEX('Draft Board'!$A$2:$AB$622,MATCH('Post-Mortem'!H13,'Draft Board'!$F$2:$F$622,0),21) -> D+ | AC13: =INDEX('Draft Board'!$A$2:$AB$622,MATCH('Post-Mortem'!I13,'Draft Board'!$F$2:$F$622,0),21) -> C+ | ... AE13: =INDEX('Draft Board'!$A$2:$AB$622,MATCH('Post-Mortem'!K13,'Draft Board'!$F$2:$F$622,0),21) -> C- | AF13: =INDEX('Draft Board'!$A$2:$AB$622,MATCH('Post-Mortem'!B13,'Draft Board'!$F$2:$F$622,0),22) -> 54 | AG13: =INDEX('Draft Board'!$A$2:$AB$622,MATCH('Post-Mortem'!C13,'Draft Board'!$F$2:$F$622,0),22) -> 71 | AH13: =INDEX('Draft Board'!$A$2:$AB$622,MATCH('Post-Mortem'!D13,'Draft Board'!$F$2:$F$622,0),22) -> 114 | AI13: =INDEX('Draft Board'!$A$2:$AB$622,MATCH('Post-Mortem'!E13,'Draft Board'!$F$2:$F$622,0),22) -> 194 | AJ13: =INDEX('Draft Board'!$A$2:$AB$622,MATCH('Post-Mortem'!F13,'Draft Board'!$F$2:$F$622,0),22) -> 233 | AK13: =INDEX('Draft Board'!$A$2:$AB$622,MATCH('Post-Mortem'!G13,'Draft Board'!$F$2:$F$622,0),22) -> 186 | AL13: =INDEX('Draft Board'!$A$2:$AB$622,MATCH('Post-Mortem'!H13,'Draft Board'!$F$2:$F$622,0),22) -> 250 | AM13: =INDEX('Draft Board'!$A$2:$AB$622,MATCH('Post-Mortem'!I13,'Draft Board'!$F$2:$F$622,0),22) -> 124 | ... AO13: =INDEX('Draft Board'!$A$2:$AB$622,MATCH('Post-Mortem'!K13,'Draft Board'!$F$2:$F$622,0),22) -> 206 | AP13: =B13-AF13 -> 47 | AQ13: =C13-AG13 -> 31 | AR13: =D13-AH13 -> -11 | AS13: =E13-AI13 -> -90 | AT13: =F13-AJ13 -> -128 | AU13: =G13-AK13 -> -80 | AV13: =H13-AL13 -> -143 | AW13: =I13-AM13 -> -16 | ... AY13: =K13-AO13 -> -96
